<?xml version="1.0" ?>
<!-- =================================================================================== -->
<!-- |    This document was autogenerated by xacro from spb_urdf.xacro               | -->
<!-- |    EDITING THIS FILE BY HAND IS NOT RECOMMENDED                                 | -->
<!-- =================================================================================== -->
<robot name="theimcbot_urdf">
  <!-- Specify some standard inertial calculations https://en.wikipedia.org/wiki/List_of_moments_of_inertia -->
  <!-- These make use of xacro's mathematical functionality -->
  <material name="Black">
    <color rgba="0.0 0.0 0.0 1.0"/>
  </material>
  <material name="Dark">
    <color rgba="0.3 0.3 0.3 1.0"/>
  </material>
  <material name="Light_black">
    <color rgba="0.4 0.4 0.4 1.0"/>
  </material>
  <material name="Blue">
    <color rgba="0.0 0.0 0.8 1.0"/>
  </material>
  <material name="Green">
    <color rgba="0.0 0.8 0.0 1.0"/>
  </material>
  <material name="Grey">
    <color rgba="0.5 0.5 0.5 1.0"/>
  </material>
  <material name="Orange">
    <color rgba="1.0 0.4235294117647059 0.0392156862745098 1.0"/>
  </material>
  <material name="Brown">
    <color rgba="0.8705882352941177 0.8117647058823529 0.7647058823529411 1.0"/>
  </material>
  <material name="Red">
    <color rgba="0.8 0.0 0.0 1.0"/>
  </material>
  <material name="White">
    <color rgba="1.0 1.0 1.0 1.0"/>
  </material>
  <material name="Cyan">
    <color rgba="0 1.0 1.0 1.0"/>
  </material>
  
  <!-- Robot Base -->
  <link name="base_link">
    <visual>
      <geometry>
        <box size="0.716 0.936 0.147"/>
      </geometry>
      <material name="Orange"/>
    </visual>
    <collision>
      <geometry>
        <box size="0.716 0.936 0.147"/>
      </geometry>
    </collision>
    <inertial>
      <origin rpy="0 0 0" xyz="0 0 0"/>
      <mass value="15.0"/> 
      <inertia ixx="1.122" ixy="0.0" ixz="0.0" iyy="0.6678" iyz="0.0" izz="1.7359"/> 
    </inertial>
  </link>
  
  <!-- Robot Footprint -->
  <link name="base_footprint">
    <inertial>
      <origin rpy="0 0 0" xyz="0 0 0"/>
      <mass value="0"/>
      <inertia ixx="0.0" ixy="0.0" ixz="0.0" iyy="0.0" iyz="0.0" izz="0.0"/>
    </inertial>
  </link>
  
  <joint name="base_joint" type="fixed">
    <parent link="base_footprint"/>
    <child link="base_link"/>
    <origin rpy="0 0 0" xyz="0.0 0.0 0.1"/>
  </joint>
  <!-- Front Left Wheel -->
  <link name="front_left_link">
    <visual>
      <origin rpy="1.5708 0 0" xyz="0 0 0"/>
      <geometry>
        <cylinder length="0.04" radius="0.08"/>
      </geometry>
      <material name="Cyan"/>
    </visual>
    <collision>
      <origin rpy="1.5708 0 0" xyz="0 0 0"/>
      <geometry>
        <cylinder length="0.04" radius="0.08"/>
      </geometry>
    </collision>
    <inertial>
      <origin rpy="0 0 0" xyz="0 0 0"/>
      <mass value="0.5"/>
      <inertia ixx="0.000866" ixy="0.0" ixz="0.0" iyy="0.0016" iyz="0.0" izz="0.000866"/>
    </inertial>
  </link>
  <joint name="front_left_joint" type="continuous">
    <parent link="base_link"/>
    <child link="front_left_link"/>
    <origin rpy="0 0 0" xyz="0.35 0.45 -0.05"/>
    <axis xyz="0 1 0"/>
  </joint>

  <!-- Front Right Wheel -->
  <link name="front_right_link">
    <visual>
      <origin rpy="1.5708 0 0" xyz="0 0 0"/>
      <geometry>
        <cylinder length="0.04" radius="0.08"/>
      </geometry>
      <material name="Cyan"/>
    </visual>
    <collision>
      <origin rpy="1.5708 0 0" xyz="0 0 0"/>
      <geometry>
        <cylinder length="0.04" radius="0.08"/>
      </geometry>
    </collision>
    <inertial>
      <origin rpy="0 0 0" xyz="0 0 0"/>
      <mass value="0.5"/>
      <inertia ixx="0.000866" ixy="0.0" ixz="0.0" iyy="0.0016" iyz="0.0" izz="0.000866"/>
    </inertial>
  </link>
  <joint name="front_right_joint" type="continuous">
    <parent link="base_link"/>
    <child link="front_right_link"/>
    <origin rpy="0 0 0" xyz="0.35 -0.45 -0.05"/>
    <axis xyz="0 1 0"/>
  </joint>

  <!-- Rear Left Wheel -->
  <link name="rear_left_link">
    <visual>
      <origin rpy="1.5708 0 0" xyz="0 0 0"/>
      <geometry>
        <cylinder length="0.04" radius="0.08"/>
      </geometry>
      <material name="Cyan"/>
    </visual>
    <collision>
      <origin rpy="1.5708 0 0" xyz="0 0 0"/>
      <geometry>
        <cylinder length="0.04" radius="0.08"/>
      </geometry>
    </collision>
    <inertial>
      <origin rpy="0 0 0" xyz="0 0 0"/>
      <mass value="0.5"/>
      <inertia ixx="0.000866" ixy="0.0" ixz="0.0" iyy="0.0016" iyz="0.0" izz="0.000866"/>
    </inertial>
  </link>
  <joint name="rear_left_joint" type="continuous">
    <parent link="base_link"/>
    <child link="rear_left_link"/>
    <origin rpy="0 0 0" xyz="-0.35 0.45 -0.05"/>
    <axis xyz="0 1 0"/>
  </joint>

  <!-- Rear Right Wheel -->
  <link name="rear_right_link">
    <visual>
      <origin rpy="1.5708 0 0" xyz="0 0 0"/>
      <geometry>
        <cylinder length="0.04" radius="0.08"/>
      </geometry>
      <material name="Cyan"/>
    </visual>
    <collision>
      <origin rpy="1.5708 0 0" xyz="0 0 0"/>
      <geometry>
        <cylinder length="0.04" radius="0.08"/>
      </geometry>
    </collision>
    <inertial>
      <origin rpy="0 0 0" xyz="0 0 0"/>
      <mass value="0.5"/>
      <inertia ixx="0.000866" ixy="0.0" ixz="0.0" iyy="0.0016" iyz="0.0" izz="0.000866"/>
    </inertial>
  </link>
  <joint name="rear_right_joint" type="continuous">
    <parent link="base_link"/>
    <child link="rear_right_link"/>
    <origin rpy="0 0 0" xyz="-0.35 -0.45 -0.05"/>
    <axis xyz="0 1 0"/>
  </joint>

  <!-- round_base_link -->
  <link name="round_base_link">
    <visual>
      <geometry>
        <cylinder length="0.097" radius="0.2"/>
      </geometry>
      <material name="Green"/>
    </visual>
    <collision>
      <geometry>
        <cylinder length="0.097" radius="0.2"/>
      </geometry>
    </collision>
    <inertial>
      <origin rpy="0 0 0" xyz="0 0 0"/>
      <mass value="2.0"/> 
      <inertia ixx="0.02156" ixy="0.0" ixz="0.0" iyy="0.02156" iyz="0.0" izz="0.04"/>
    </inertial>
  </link>
  
  <joint name="round_base_joint" type="fixed">
    <parent link="base_link"/>
    <child link="round_base_link"/>
    <origin rpy="0 0 0" xyz="0 0.0 0.1"/>
  </joint>
  
  <!-- stick_link -->
  <link name="stick_link">
    <visual>
      <geometry>
        <cylinder length="0.897" radius="0.03"/>
      </geometry>
      <material name="Green"/>
    </visual>
    <collision>
      <geometry>
        <cylinder length="0.897" radius="0.03"/>
      </geometry>
    </collision>
    <inertial>
      <origin rpy="0 0 0" xyz="0 0 0"/>
      <mass value="1.0"/> 
      <inertia ixx="0.06727" ixy="0.0" ixz="0.0" iyy="0.06727" iyz="0.0" izz="0.00045"/>
    </inertial>
  </link>
  
  <joint name="stick_joint" type="fixed">
    <parent link="round_base_link"/>
    <child link="stick_link"/>
    <origin rpy="0 0 0" xyz="0 0 0.5"/>
  </joint>
  
    <!-- head -->
  <link name="head_link">
    <visual>
      <geometry>
        <box size="0.4 0.133 0.07"/>
      </geometry>
      <material name="Green"/>
    </visual>
    <collision>
      <geometry>
        <box size="0.4 0.133 0.07"/>
      </geometry>
    </collision>
    <inertial>
      <origin rpy="0 0 0" xyz="0 0 0"/>
      <mass value="3.0"/>
      <inertia ixx="0.005647" ixy="0.0" ixz="0.0" iyy="0.041225" iyz="0.0" izz="0.04442"/> 
    </inertial>
  </link>
  
  <joint name="head_joint" type="fixed">
    <parent link="stick_link"/>
    <child link="head_link"/>
    <origin rpy="0 0 0" xyz="0 0 0.48"/>
  </joint>
  
  
  <!-- lidar_link -->
  <joint name="lidar_joint" type="fixed">
    <parent link="base_link"/>
    <child link="lidar_link"/>
    <origin rpy="0 0 0" xyz="0.258 0 0.0725"/>
  </joint>

  <link name="lidar_link">
    <visual>
      <geometry>
        <cylinder length="0.02" radius="0.03"/>
      </geometry>
      <material name="Blue"/>
    </visual>
    <visual>
      <origin xyz="0 0 0.02"/>
      <geometry>
        <cylinder length="0.045" radius="0.03"/>
      </geometry>
      <material name="Black"/>
    </visual>
    <collision>
      <geometry>
        <cylinder length="0.065" radius="0.03"/>  
      </geometry>
    </collision>
    <inertial>
      <origin rpy="0 0 0" xyz="0 0 0"/>
      <mass value="0.2"/> 
      <inertia ixx="0.00009006" ixy="0.0" ixz="0.0" iyy="0.00009006" iyz="0.0" izz="0.00009"/> 
    </inertial>
  </link>
  
  <link name="camera_link">
    <visual>
      <geometry>
        <box size="0.09 0.01 0.017"/>
      </geometry>
      <material name="Red"/>
    </visual>
    <visual>
      <origin xyz="0 0 0"/>
      <geometry>
        <box size="0.09 0.01 0.017"/>
      </geometry>
      <material name="Red"/>
    </visual>
    <collision>
      <geometry>
        <box size="0.09 0.01 0.017"/>
      </geometry>
    </collision>
    <inertial>
      <origin rpy="0 0 0" xyz="0 0 0"/>
      <mass value="0.05"/> 
      <inertia ixx="0.00000162" ixy="0.0" ixz="0.0" iyy="0.00003495" iyz="0.0" izz="0.00003416"/> 
    </inertial>
  </link>
  
  <joint name="camera_joint" type="fixed">
    <parent link="head_link"/>
    <child link="camera_link"/>
    <origin rpy="0 0 0" xyz="0.15 -0.06 0.0"/>
  </joint>
  
  <joint name="camera_optical_joint" type="fixed">
    <parent link="camera_link"/>
    <child link="camera_optical_link"/>
    <origin rpy="0 0 0" xyz="0 0 0"/>
  </joint>
  <link name="camera_optical_link"/>
  
  <joint name="imu_joint" type="fixed">
    <parent link="head_link"/>
    <child link="imu_link"/>
    <origin rpy="0 0 0" xyz="0 0 0.0"/>
  </joint>
  
  <link name="imu_link">
    <visual>
      <geometry>
        <box size="0.05 0.1 0.01"/>
      </geometry>
      <material name="Brown"/>
    </visual>
    <collision>
      <geometry>
        <box size="0.05 0.1 0.01"/>
      </geometry>
    </collision>
    <inertial>
      <origin rpy="0 0 0" xyz="0 0 0"/>
      <mass value="0.02"/>
      <inertia ixx="0.00001683" ixy="0.0" ixz="0.0" iyy="0.00000433" iyz="0.0" izz="0.00002083"/>
    </inertial>
  </link>
</robot>

